<?xml version="1.0" encoding="UTF-8"?>
<robot generator="Robot 3.1.2 (Python 3.8.1 on win32)" generated="20200308 19:59:25.973" rpa="false">
<suite id="s1" name="Post. User" source="C:\robotFramework\ninjaplus\specs\api\post._user.robot">
<test id="s1-t1" name="Create a new user">
<kw name="remove user by email">
<arguments>
<arg>bruc@wayne.com</arg>
</arguments>
<msg timestamp="20200308 19:59:28.085" level="FAIL">No keyword with name 'remove user by email' found.</msg>
<status status="FAIL" starttime="20200308 19:59:28.085" endtime="20200308 19:59:28.086"></status>
</kw>
<status status="FAIL" starttime="20200308 19:59:28.078" endtime="20200308 19:59:28.086" critical="yes">No keyword with name 'remove user by email' found.</status>
</test>
<test id="s1-t2" name="Email required">
<kw name="Create Session" library="RequestsLibrary">
<doc>Create Session: create a HTTP session to a server</doc>
<arguments>
<arg>nplus</arg>
<arg>http://ninjaplus-api:3000</arg>
</arguments>
<msg timestamp="20200308 19:59:28.092" level="INFO">Creating Session using : alias=nplus, url=http://ninjaplus-api:3000, headers={},                     cookies={}, auth=None, timeout=None, proxies=None, verify=False,                     debug=0 </msg>
<status status="PASS" starttime="20200308 19:59:28.091" endtime="20200308 19:59:28.092"></status>
</kw>
<kw name="Create Dictionary" library="BuiltIn">
<doc>Creates and returns a dictionary based on the given ``items``.</doc>
<arguments>
<arg>full_name=Bruci Wayne</arg>
<arg>email=${EMPTY}</arg>
<arg>password=pwd123</arg>
</arguments>
<assign>
<var>&amp;{body}</var>
</assign>
<msg timestamp="20200308 19:59:28.106" level="INFO">&amp;{body} = { full_name=Bruci Wayne | email= | password=pwd123 }</msg>
<status status="PASS" starttime="20200308 19:59:28.093" endtime="20200308 19:59:28.106"></status>
</kw>
<kw name="Create Dictionary" library="BuiltIn">
<doc>Creates and returns a dictionary based on the given ``items``.</doc>
<arguments>
<arg>Content-Type=application/json</arg>
</arguments>
<assign>
<var>&amp;{headers}</var>
</assign>
<msg timestamp="20200308 19:59:28.108" level="INFO">&amp;{headers} = { Content-Type=application/json }</msg>
<status status="PASS" starttime="20200308 19:59:28.107" endtime="20200308 19:59:28.108"></status>
</kw>
<kw name="Post Request" library="RequestsLibrary">
<doc>Send a POST request on the session object found using the
given `alias`</doc>
<arguments>
<arg>nplus</arg>
<arg>/user</arg>
<arg>data=${body}</arg>
<arg>headers=${headers}</arg>
</arguments>
<assign>
<var>${response}</var>
</assign>
<msg timestamp="20200308 19:59:28.120" level="INFO">POST Request using : uri=/user, params=None, files=None, allow_redirects=True, timeout=None
headers={'User-Agent': 'python-requests/2.23.0', 'Accept-Encoding': 'gzip, deflate', 'Accept': '*/*', 'Connection': 'keep-alive', 'Content-Type': 'application/json'} 
data={"full_name": "Bruci Wayne", "email": "", "password": "pwd123"} 
json=None</msg>
<msg timestamp="20200308 19:59:29.369" level="WARN">Retrying (Retry(total=2, connect=None, read=None, redirect=None, status=None)) after connection broken by 'NewConnectionError('&lt;urllib3.connection.HTTPConnection object at 0x0000019E7B14DC70&gt;: Failed to establish a new connection: [WinError 10061] Nenhuma conexão pôde ser feita porque a máquina de destino as recusou ativamente')': /user</msg>
<msg timestamp="20200308 19:59:30.730" level="WARN">Retrying (Retry(total=1, connect=None, read=None, redirect=None, status=None)) after connection broken by 'NewConnectionError('&lt;urllib3.connection.HTTPConnection object at 0x0000019E7B14DEB0&gt;: Failed to establish a new connection: [WinError 10061] Nenhuma conexão pôde ser feita porque a máquina de destino as recusou ativamente')': /user</msg>
<msg timestamp="20200308 19:59:32.229" level="WARN">Retrying (Retry(total=0, connect=None, read=None, redirect=None, status=None)) after connection broken by 'NewConnectionError('&lt;urllib3.connection.HTTPConnection object at 0x0000019E7B1850A0&gt;: Failed to establish a new connection: [WinError 10061] Nenhuma conexão pôde ser feita porque a máquina de destino as recusou ativamente')': /user</msg>
<msg timestamp="20200308 19:59:33.405" level="FAIL">ConnectionError: HTTPConnectionPool(host='ninjaplus-api', port=3000): Max retries exceeded with url: /user (Caused by NewConnectionError('&lt;urllib3.connection.HTTPConnection object at 0x0000019E7B185280&gt;: Failed to establish a new connection: [WinError 10061] Nenhuma conexão pôde ser feita porque a máquina de destino as recusou ativamente'))</msg>
<status status="FAIL" starttime="20200308 19:59:28.119" endtime="20200308 19:59:33.405"></status>
</kw>
<status status="FAIL" starttime="20200308 19:59:28.090" endtime="20200308 19:59:33.406" critical="yes">ConnectionError: HTTPConnectionPool(host='ninjaplus-api', port=3000): Max retries exceeded with url: /user (Caused by NewConnectionError('&lt;urllib3.connection.HTTPConnection object at 0x0000019E7B185280&gt;: Failed to establish a new connection: [WinError 10061] Nenhuma conexão pôde ser feita porque a máquina de destino as recusou ativamente'))</status>
</test>
<status status="FAIL" starttime="20200308 19:59:25.979" endtime="20200308 19:59:33.410"></status>
</suite>
<statistics>
<total>
<stat pass="0" fail="2">Critical Tests</stat>
<stat pass="0" fail="2">All Tests</stat>
</total>
<tag>
</tag>
<suite>
<stat pass="0" fail="2" id="s1" name="Post. User">Post. User</stat>
</suite>
</statistics>
<errors>
<msg timestamp="20200308 19:59:28.070" level="ERROR">Error in file 'C:\robotFramework\ninjaplus\specs\api\post._user.robot': Importing test library 'C:\robotFramework\ninjaplus\resources\lib\db.py' failed: OperationalError: could not connect to server: Connection refused (0x0000274D/10061)
	Is the server running on host "pgdb" (127.0.0.1) and accepting
	TCP/IP connections on port 5432?

Traceback (most recent call last):
  File "C:\robotFramework\ninjaplus\resources\lib\db.py", line 3, in &lt;module&gt;
    conn = psycopg2.connect(host='pgdb', database='ninjaplus', user='postgres', password='qaninja')
  File "c:\python38\lib\site-packages\psycopg2\__init__.py", line 126, in connect
    conn = _connect(dsn, connection_factory=connection_factory, **kwasync)
PYTHONPATH:
  C:\Python38\Scripts\robot.exe
  c:\python38\python38.zip
  c:\python38\DLLs
  c:\python38\lib
  c:\python38
  C:\Users\ohnir\AppData\Roaming\Python\Python38\site-packages
  c:\python38\lib\site-packages</msg>
<msg timestamp="20200308 19:59:29.369" level="WARN">Retrying (Retry(total=2, connect=None, read=None, redirect=None, status=None)) after connection broken by 'NewConnectionError('&lt;urllib3.connection.HTTPConnection object at 0x0000019E7B14DC70&gt;: Failed to establish a new connection: [WinError 10061] Nenhuma conexão pôde ser feita porque a máquina de destino as recusou ativamente')': /user</msg>
<msg timestamp="20200308 19:59:30.730" level="WARN">Retrying (Retry(total=1, connect=None, read=None, redirect=None, status=None)) after connection broken by 'NewConnectionError('&lt;urllib3.connection.HTTPConnection object at 0x0000019E7B14DEB0&gt;: Failed to establish a new connection: [WinError 10061] Nenhuma conexão pôde ser feita porque a máquina de destino as recusou ativamente')': /user</msg>
<msg timestamp="20200308 19:59:32.229" level="WARN">Retrying (Retry(total=0, connect=None, read=None, redirect=None, status=None)) after connection broken by 'NewConnectionError('&lt;urllib3.connection.HTTPConnection object at 0x0000019E7B1850A0&gt;: Failed to establish a new connection: [WinError 10061] Nenhuma conexão pôde ser feita porque a máquina de destino as recusou ativamente')': /user</msg>
</errors>
</robot>
